[2023-11-06T16:09:23.166+0000] {taskinstance.py:1159} INFO - Dependencies all met for dep_context=non-requeueable deps ti=<TaskInstance: ETL_Processing.load manual__2023-11-06T16:04:38.526641+00:00 [queued]>
[2023-11-06T16:09:23.233+0000] {taskinstance.py:1159} INFO - Dependencies all met for dep_context=requeueable deps ti=<TaskInstance: ETL_Processing.load manual__2023-11-06T16:04:38.526641+00:00 [queued]>
[2023-11-06T16:09:23.238+0000] {taskinstance.py:1361} INFO - Starting attempt 1 of 1
[2023-11-06T16:09:23.338+0000] {taskinstance.py:1382} INFO - Executing <Task(BashOperator): load> on 2023-11-06 16:04:38.526641+00:00
[2023-11-06T16:09:23.373+0000] {standard_task_runner.py:57} INFO - Started process 230 to run task
[2023-11-06T16:09:23.386+0000] {standard_task_runner.py:84} INFO - Running: ['***', 'tasks', 'run', 'ETL_Processing', 'load', 'manual__2023-11-06T16:04:38.526641+00:00', '--job-id', '22', '--raw', '--subdir', 'DAGS_FOLDER/ETL_Python.py', '--cfg-path', '/tmp/tmp_rxm5dcu']
[2023-11-06T16:09:23.396+0000] {standard_task_runner.py:85} INFO - Job 22: Subtask load
[2023-11-06T16:09:24.664+0000] {task_command.py:416} INFO - Running <TaskInstance: ETL_Processing.load manual__2023-11-06T16:04:38.526641+00:00 [running]> on host 07361dfe1645
[2023-11-06T16:09:26.504+0000] {taskinstance.py:1662} INFO - Exporting env vars: AIRFLOW_CTX_DAG_OWNER='Mike Lozada' AIRFLOW_CTX_DAG_ID='ETL_Processing' AIRFLOW_CTX_TASK_ID='load' AIRFLOW_CTX_EXECUTION_DATE='2023-11-06T16:04:38.526641+00:00' AIRFLOW_CTX_TRY_NUMBER='1' AIRFLOW_CTX_DAG_RUN_ID='manual__2023-11-06T16:04:38.526641+00:00'
[2023-11-06T16:09:26.525+0000] {subprocess.py:63} INFO - Tmp dir root location: /tmp
[2023-11-06T16:09:26.532+0000] {subprocess.py:75} INFO - Running command: ['/bin/bash', '-c', 'zip log.zip capitalized.txt']
[2023-11-06T16:09:26.616+0000] {subprocess.py:86} INFO - Output:
[2023-11-06T16:09:26.629+0000] {subprocess.py:93} INFO - /bin/bash: line 1: zip: command not found
[2023-11-06T16:09:26.641+0000] {subprocess.py:97} INFO - Command exited with return code 127
[2023-11-06T16:09:27.153+0000] {taskinstance.py:1937} ERROR - Task failed with exception
Traceback (most recent call last):
  File "/home/airflow/.local/lib/python3.8/site-packages/airflow/operators/bash.py", line 210, in execute
    raise AirflowException(
airflow.exceptions.AirflowException: Bash command failed. The command returned a non-zero exit code 127.
[2023-11-06T16:09:27.441+0000] {taskinstance.py:1400} INFO - Marking task as FAILED. dag_id=ETL_Processing, task_id=load, execution_date=20231106T160438, start_date=20231106T160923, end_date=20231106T160927
[2023-11-06T16:09:28.240+0000] {standard_task_runner.py:104} ERROR - Failed to execute job 22 for task load (Bash command failed. The command returned a non-zero exit code 127.; 230)
[2023-11-06T16:09:28.345+0000] {local_task_job_runner.py:228} INFO - Task exited with return code 1
[2023-11-06T16:09:28.723+0000] {taskinstance.py:2778} INFO - 0 downstream tasks scheduled from follow-on schedule check
